Workbook
Name Slicer_M_C5: #N/A
Name Slicer_M_C4: #N/A
Name Slicer_M_C2: #N/A
Name Slicer_M_C1: #N/A
Name Slicer_Shift: #N/A
Name Slicer_Date: #N/A
Name Slicer_M_C: #N/A
Name Slicer_M_C3: #N/A
Name _3299.00: #REF!
Name HARSHAD: #REF!

Sheet PD REPORT
E1: IN Running REJ. | F1: Grinding Reworkork | G1: *** | H1: *** | I1: *** | J1: *** | L1: *** | N1: *** | P1: 0 | Q1: 0 | R1: 0 | S1: 0 | T1: 0 | U1: 0 | V1: 0 | W1: 0 | X1: 0 | Y1: 0 | Z1: 0 | AA1: 0 | AB1: 0 | AC1: 0 | AD1: 0 | AE1: 0 | AF1: 0 | AG1: 0 | AH1: 0 | AI1: 0 | AJ1: 0 | AK1: 0 | AL1: 0 | AM1: 0 | AN1: 0 | AO1: 0 | AP1: 0 | AQ1: 0
E2: =#REF! -> #REF! | H2: b | J2: IR | L2: OR
Q3: IG | R3: =SUMIFS($R$7:$R$135,$D$7:$D$135,$D$4) -> 848 | S3: =SUMIFS(#REF!,#REF!,$D$4) -> #REF! | T3: =SUMIFS(#REF!,#REF!,$D$4) -> #REF!
D4: IG | K4: IG section rework and rejction | Q4: =SUMIFS(#REF!,#REF!,$D$4) -> #REF! | R4: =(SUMIFS(#REF!,#REF!,$D$4)/Q4)*100 -> #REF! | S4: =(SUMIFS(#REF!,#REF!,$D$4)/Q4)*100 -> #REF! | U4: =SUMIFS(#REF!,#REF!,$D$4) -> #REF!
A5: SR NO | B5: Date | C5: Shift | D5: M/C | E5: M/c | F5: Opt | G5: Name 1 | H5: Name 2 | I5: Name 3 | J5: ITEM CODE | K5: ITEM NAME | L5: BATCH NO | M5: .OR/ IR | N5: Cycle time | O5: P.H.P | P5: PASS | Q5: Good | R5: Rework | S5: IN Running REJ. | T5: T.R | U5: Total | V5: Working MINUTES | W5: New Setting 10 | X5: RE SETTING,LODING | Y5: Ovality Problem 11Ov | Z5: Taper Problem 11Tp | AA5: Ra Problem 11Ra | AB5: Raadiua Problem 11Rd | AC5: Size variation Problem 11 Sv IPG Pro | AD5: Roundness Problem 11Ro | AE5: Diamond Turn 11Dt | AF5: Diamond change 11Dc | AG5: Straightness Problem 11St | AH5: Finishing Problem 11Fn | AI5: Vibration Problem 11Vb | AJ5: Step Problem 11Sp | AK5: Squareness problem 11Sq | AL5: Burning Problem 11Br | AM5: Tool Waiting 12 | AN5: No Material 14(INTERNAL) | AO5: Q.C. Waiting 19 | AP5: Wheel Change 17 | AQ5: Wheel Dressing 18 | AR5: No Operator 13 | AS5: New Operator 15 | AT5: Material Defect 16 | AU5: No Material 14(EXTERNAL) | AV5: Under Trial 20 | AW5: Mech.Maint.21 | AX5: Elec. Maint. 22 | AY5: Prev. Maint. 23 | AZ5: No Power 24 | BA5: No Air 25 | BB5: No Coolant 26 | BC5: Other 27 | BD5: Oiling 28 | BE5: M/c Cleaning 29 | BF5: Not In Plan 30 | BG5: TOTAL | BH5: Plan Hrs | BI5: 0 | BJ5: Availability ( Ar ) = x/a (%) | BK5: Net Performance (Pr)=(o*n)/ (x*3600) (%) | BL5: Quality rate (Qr)=(o-p)/o (%) | BM5: O.E.E= Ar*Pr*Cr (%) | BN5: AD | BO5: M/C Plan Qty. | BP5: Down Time (Hrs) | BQ5: Total Loss Qty. | BR5: RA CHECK | BS5: Step check | BT5: ROUNDNESS | BU5: STRAIGTNESS | BV5: Radius | BW5: no.of pass x good qty | XFD5: =SUM(A5:XFC5) -> 0
A6: 0 | W6: 10 | X6: 11 | Y6: 11OV | Z6: 11TP | AA6: 11RA | AB6: 11RD | AC6: 11SV | AD6: 11RO | AE6: 11DT | AF6: 11DC | AG6: 11ST | AH6: 11FN | AI6: 11VB | AJ6: 11SP | AK6: 11SQ | AL6: 11BR | AM6: 12 | AN6: 14 IN | AO6: 19 | AP6: 17 | AQ6: 18 | AR6: 13 | AS6: 15 | AT6: 16 | AU6: 14( EX) | AV6: 20 | AW6: 21 | AX6: 22 | AY6: 23 | AZ6: 24 | BA6: 25 | BB6: 26 | BC6: 27 | BD6: 28 | BE6: 29 | BF6: 30
A7: 1 | B7: 46054 | C7: I | D7: =LEFT(E7,2) -> FG | E7: FG.03 | K7: =VLOOKUP(J7,'[3]Item List (3)'!A$1:B$110000,2,FALSE) -> #N/A | M7: =IF((LEFT(J7))="2",$L$2,$J$2) -> IR | O7: =IFERROR(3600/N7,"") | U7: =Q7+S7+T7 -> 0 | AR7: 480 | BG7: =SUM(V7:BF7) -> 480 | BH7: =BG7/60 -> 8 | BI7: =IFERROR(BH7-SUM(W7:BF7)/60,0) -> 0 | BJ7: =IFERROR(BI7/BH7*100,0) -> 0 | BK7: =IFERROR(((U7*N7)/(BI7*3600)*100),0) -> 0 | BL7: =IFERROR(((U7-(R7+S7+T7))/U7*100),0) -> 0 | BM7: =IFERROR((((BJ7*BK7*BL7)/1000000)*100),0) -> 0 | BN7: =(W7+AP7+BE7+BF7)/60 -> 0 | BO7: =IFERROR(((BH7-BN7)*3600)/N7,0) -> 0 | BP7: =IFERROR(SUM(W7:BF7)/60-BN7,0) -> 8 | BQ7: =IFERROR(BP7*3600/N7,0) -> 0 | BW7: =Q7*P7 -> 0
A8: 2 | B8: 46054 | C8: II | D8: =LEFT(E8,2) -> FG | E8: FG.03 | F8: RFG | G8: Nareshbhai Rathod | H8: Sanjay | J8: 104343.01 | K8: =VLOOKUP(J8,'[3]Item List (3)'!A$1:B$110000,2,FALSE) -> NA/RNA.IR 69/32 | L8: 260101001 | M8: =IF((LEFT(J8))="2",$L$2,$J$2) -> IR | O8: =IFERROR(3600/N8,"") | P8: 1 | Q8: 967 | S8: 5 | U8: =Q8+S8+T8 -> 972 | V8: 210 | X8: 60 | AP8: 150 | AQ8: 60 | BG8: =SUM(V8:BF8) -> 480 | BH8: =BG8/60 -> 8 | BI8: =IFERROR(BH8-SUM(W8:BF8)/60,0) -> 3.5 | BJ8: =IFERROR(BI8/BH8*100,0) -> 43.75 | BK8: =IFERROR(((U8*N8)/(BI8*3600)*100),0) -> 0 | BL8: =IFERROR(((U8-(R8+S8+T8))/U8*100),0) -> 99.485597 | BM8: =IFERROR((((BJ8*BK8*BL8)/1000000)*100),0) -> 0 | BN8: =(W8+AP8+BE8+BF8)/60 -> 2.5 | BO8: =IFERROR(((BH8-BN8)*3600)/N8,0) -> 0 | BP8: =IFERROR(SUM(W8:BF8)/60-BN8,0) -> 2 | BQ8: =IFERROR(BP8*3600/N8,0) -> 0 | BW8: =Q8*P8 -> 967
A9: 3 | B9: 46054 | C9: I | D9: =LEFT(E9,2) -> FG | E9: FG.04 | F9: RFG | G9: Ketan | H9: Sunil | J9: 104299 | K9: =VLOOKUP(J9,'[3]Item List (3)'!A$1:B$110000,2,FALSE) -> IR.9916 | L9: 260107018 | M9: =IF((LEFT(J9))="2",$L$2,$J$2) -> IR | O9: =IFERROR(3600/N9,"") | P9: 1 | Q9: 5000 | U9: =Q9+S9+T9 -> 5000 | V9: 180 | AQ9: 120 | AR9: 120 | BG9: =SUM(V9:BF9) -> 420 | BH9: =BG9/60 -> 7 | BI9: =IFERROR(BH9-SUM(W9:BF9)/60,0) -> 3 | BJ9: =IFERROR(BI9/BH9*100,0) -> 42.857143 | BK9: =IFERROR(((U9*N9)/(BI9*3600)*100),0) -> 0 | BL9: =IFERROR(((U9-(R9+S9+T9))/U9*100),0) -> 100 | BM9: =IFERROR((((BJ9*BK9*BL9)/1000000)*100),0) -> 0 | BN9: =(W9+AP9+BE9+BF9)/60 -> 0 | BO9: =IFERROR(((BH9-BN9)*3600)/N9,0) -> 0 | BP9: =IFERROR(SUM(W9:BF9)/60-BN9,0) -> 4 | BQ9: =IFERROR(BP9*3600/N9,0) -> 0 | BW9: =Q9*P9 -> 5000
A10: 4 | B10: 46054 | C10: I | D10: =LEFT(E10,2) -> FG | E10: FG.04 | F10: FG | G10: Ketan | H10: Sunil | J10: 104299 | K10: =VLOOKUP(J10,'[3]Item List (3)'!A$1:B$110000,2,FALSE) -> IR.9916 | L10: 260107018 | M10: =IF((LEFT(J10))="2",$L$2,$J$2) -> IR | O10: =IFERROR(3600/N10,"") | P10: 1 | Q10: 500 | U10: =Q10+S10+T10 -> 500 | V10: 60 | BG10: =SUM(V10:BF10) -> 60 | BH10: =BG10/60 -> 1 | BI10: =IFERROR(BH10-SUM(W10:BF10)/60,0) -> 1 | BJ10: =IFERROR(BI10/BH10*100,0) -> 100 | BK10: =IFERROR(((U10*N10)/(BI10*3600)*100),0) -> 0 | BL10: =IFERROR(((U10-(R10+S10+T10))/U10*100),0) -> 100 | BM10: =IFERROR((((BJ10*BK10*BL10)/1000000)*100),0) -> 0 | BN10: =(W10+AP10+BE10+BF10)/60 -> 0 | BO10: =IFERROR(((BH10-BN10)*3600)/N10,0) -> 0 | BP10: =IFERROR(SUM(W10:BF10)/60-BN10,0) -> 0 | BQ10: =IFERROR(BP10*3600/N10,0) -> 0 | BW10: =Q10*P10 -> 500
A11: 5 | B11: 46054 | C11: II | D11: =LEFT(E11,2) -> FG | E11: FG.04 | F11: FG | G11: Sunil | H11: Vishal | J11: 104299 | K11: =VLOOKUP(J11,'[3]Item List (3)'!A$1:B$110000,2,FALSE) -> IR.9916 | L11: 260107018 | M11: =IF((LEFT(J11))="2",$L$2,$J$2) -> IR | O11: =IFERROR(3600/N11,"") | P11: 1 | Q11: 7000 | U11: =Q11+S11+T11 -> 7000 | V11: 240 | AQ11: 120 | BG11: =SUM(V11:BF11) -> 360 | BH11: =BG11/60 -> 6 | BI11: =IFERROR(BH11-SUM(W11:BF11)/60,0) -> 4 | BJ11: =IFERROR(BI11/BH11*100,0) -> 66.666667 | BK11: =IFERROR(((U11*N11)/(BI11*3600)*100),0) -> 0 | BL11: =IFERROR(((U11-(R11+S11+T11))/U11*100),0) -> 100 | BM11: =IFERROR((((BJ11*BK11*BL11)/1000000)*100),0) -> 0 | BN11: =(W11+AP11+BE11+BF11)/60 -> 0 | BO11: =IFERROR(((BH11-BN11)*3600)/N11,0) -> 0 | BP11: =IFERROR(SUM(W11:BF11)/60-BN11,0) -> 2 | BQ11: =IFERROR(BP11*3600/N11,0) -> 0 | BW11: =Q11*P11 -> 7000
A12: 6 | B12: 46054 | C12: II | D12: =LEFT(E12,2) -> FG | E12: FG.04 | F12: Light Cut | G12: Sunil | H12: Vishal | J12: 104281 | K12: =VLOOKUP(J12,'[3]Item List (3)'!A$1:B$110000,2,FALSE) -> D.IR 14536 | L12: 251223015 | M12: =IF((LEFT(J12))="2",$L$2,$J$2) -> IR | O12: =IFERROR(3600/N12,"") | P12: 1 | Q12: 385 | U12: =Q12+S12+T12 -> 385 | V12: 60 | W12: 60 | BG12: =SUM(V12:BF12) -> 120 | BH12: =BG12/60 -> 2 | BI12: =IFERROR(BH12-SUM(W12:BF12)/60,0) -> 1 | BJ12: =IFERROR(BI12/BH12*100,0) -> 50 | BK12: =IFERROR(((U12*N12)/(BI12*3600)*100),0) -> 0 | BL12: =IFERROR(((U12-(R12+S12+T12))/U12*100),0) -> 100 | BM12: =IFERROR((((BJ12*BK12*BL12)/1000000)*100),0) -> 0 | BN12: =(W12+AP12+BE12+BF12)/60 -> 1 | BO12: =IFERROR(((BH12-BN12)*3600)/N12,0) -> 0 | BP12: =IFERROR(SUM(W12:BF12)/60-BN12,0) -> 0 | BQ12: =IFERROR(BP12*3600/N12,0) -> 0 | BW12: =Q12*P12 -> 385
A13: 7 | B13: 46054 | C13: I | D13: =LEFT(E13,2) -> CG | E13: CG.02 | K13: =VLOOKUP(J13,'[3]Item List (3)'!A$1:B$110000,2,FALSE) -> #N/A | M13: =IF((LEFT(J13))="2",$L$2,$J$2) -> IR | O13: =IFERROR(3600/N13,"") | U13: =Q13+S13+T13 -> 0 | BF13: 480 | BG13: =SUM(V13:BF13) -> 480 | BH13: =BG13/60 -> 8 | BI13: =IFERROR(BH13-SUM(W13:BF13)/60,0) -> 0 | BJ13: =IFERROR(BI13/BH13*100,0) -> 0 | BK13: =IFERROR(((U13*N13)/(BI13*3600)*100),0) -> 0 | BL13: =IFERROR(((U13-(R13+S13+T13))/U13*100),0) -> 0 | BM13: =IFERROR((((BJ13*BK13*BL13)/1000000)*100),0) -> 0 | BN13: =(W13+AP13+BE13+BF13)/60 -> 8 | BO13: =IFERROR(((BH13-BN13)*3600)/N13,0) -> 0 | BP13: =IFERROR(SUM(W13:BF13)/60-BN13,0) -> 0 | BQ13: =IFERROR(BP13*3600/N13,0) -> 0 | BW13: =Q13*P13 -> 0
A14: 8 | B14: 46054 | C14: II | D14: =LEFT(E14,2) -> CG | E14: CG.02 | K14: =VLOOKUP(J14,'[3]Item List (3)'!A$1:B$110000,2,FALSE) -> #N/A | M14: =IF((LEFT(J14))="2",$L$2,$J$2) -> IR | O14: =IFERROR(3600/N14,"") | U14: =Q14+S14+T14 -> 0 | BF14: 480 | BG14: =SUM(V14:BF14) -> 480 | BH14: =BG14/60 -> 8 | BI14: =IFERROR(BH14-SUM(W14:BF14)/60,0) -> 0 | BJ14: =IFERROR(BI14/BH14*100,0) -> 0 | BK14: =IFERROR(((U14*N14)/(BI14*3600)*100),0) -> 0 | BL14: =IFERROR(((U14-(R14+S14+T14))/U14*100),0) -> 0 | BM14: =IFERROR((((BJ14*BK14*BL14)/1000000)*100),0) -> 0 | BN14: =(W14+AP14+BE14+BF14)/60 -> 8 | BO14: =IFERROR(((BH14-BN14)*3600)/N14,0) -> 0 | BP14: =IFERROR(SUM(W14:BF14)/60-BN14,0) -> 0 | BQ14: =IFERROR(BP14*3600/N14,0) -> 0 | BW14: =Q14*P14 -> 0
A15: 9 | B15: 46054 | C15: I | D15: =LEFT(E15,2) -> CG | E15: CG.03 | F15: RODG | G15: Kalpeshbhai Vasoya | H15: Umang | J15: 200261 | K15: =VLOOKUP(J15,'[3]Item List (3)'!A$1:B$110000,2,FALSE) -> OR.211 YY4 | L15: 260116005 | M15: =IF((LEFT(J15))="2",$L$2,$J$2) -> OR | O15: =IFERROR(3600/N15,"") | P15: 2 | Q15: 4741 | U15: =Q15+S15+T15 -> 4741 | V15: 180 | AQ15: 75 | BG15: =SUM(V15:BF15) -> 255 | BH15: =BG15/60 -> 4.25 | BI15: =IFERROR(BH15-SUM(W15:BF15)/60,0) -> 3 | BJ15: =IFERROR(BI15/BH15*100,0) -> 70.588235 | BK15: =IFERROR(((U15*N15)/(BI15*3600)*100),0) -> 0 | BL15: =IFERROR(((U15-(R15+S15+T15))/U15*100),0) -> 100 | BM15: =IFERROR((((BJ15*BK15*BL15)/1000000)*100),0) -> 0 | BN15: =(W15+AP15+BE15+BF15)/60 -> 0 | BO15: =IFERROR(((BH15-BN15)*3600)/N15,0) -> 0 | BP15: =IFERROR(SUM(W15:BF15)/60-BN15,0) -> 1.25 | BQ15: =IFERROR(BP15*3600/N15,0) -> 0 | BW15: =Q15*P15 -> 9482
A16: 10 | B16: 46054 | C16: I | D16: =LEFT(E16,2) -> CG | E16: CG.03 | F16: FODG | G16: Kalpeshbhai Vasoya | H16: Umang | J16: 200261 | K16: =VLOOKUP(J16,'[3]Item List (3)'!A$1:B$110000,2,FALSE) -> OR.211 YY4 | L16: 260116005 | M16: =IF((LEFT(J16))="2",$L$2,$J$2) -> OR | O16: =IFERROR(3600/N16,"") | P16: 3 | Q16: 1416 | U16: =Q16+S16+T16 -> 1416 | V16: 180 | BG16: =SUM(V16:BF16) -> 180 | BH16: =BG16/60 -> 3 | BI16: =IFERROR(BH16-SUM(W16:BF16)/60,0) -> 3 | BJ16: =IFERROR(BI16/BH16*100,0) -> 100 | BK16: =IFERROR(((U16*N16)/(BI16*3600)*100),0) -> 0 | BL16: =IFERROR(((U16-(R16+S16+T16))/U16*100),0) -> 100 | BM16: =IFERROR((((BJ16*BK16*BL16)/1000000)*100),0) -> 0 | BN16: =(W16+AP16+BE16+BF16)/60 -> 0 | BO16: =IFERROR(((BH16-BN16)*3600)/N16,0) -> 0 | BP16: =IFERROR(SUM(W16:BF16)/60-BN16,0) -> 0 | BQ16: =IFERROR(BP16*3600/N16,0) -> 0 | BW16: =Q16*P16 -> 4248
A17: 11 | B17: 46054 | C17: I | D17: =LEFT(E17,2) -> CG | E17: CG.03 | G17: Kalpeshbhai Vasoya | H17: Umang | J17: 208246 | K17: =VLOOKUP(J17,'[3]Item List (3)'!A$1:B$110000,2,FALSE) -> OR. 208 YY2 | M17: =IF((LEFT(J17))="2",$L$2,$J$2) -> OR | O17: =IFERROR(3600/N17,"") | S17: 63 | U17: =Q17+S17+T17 -> 63 | V17: 45 | BG17: =SUM(V17:BF17) -> 45 | BH17: =BG17/60 -> 0.75 | BI17: =IFERROR(BH17-SUM(W17:BF17)/60,0) -> 0.75 | BJ17: =IFERROR(BI17/BH17*100,0) -> 100 | BK17: =IFERROR(((U17*N17)/(BI17*3600)*100),0) -> 0 | BL17: =IFERROR(((U17-(R17+S17+T17))/U17*100),0) -> 0 | BM17: =IFERROR((((BJ17*BK17*BL17)/1000000)*100),0) -> 0 | BN17: =(W17+AP17+BE17+BF17)/60 -> 0 | BO17: =IFERROR(((BH17-BN17)*3600)/N17,0) -> 0 | BP17: =IFERROR(SUM(W17:BF17)/60-BN17,0) -> 0 | BQ17: =IFERROR(BP17*3600/N17,0) -> 0 | BW17: =Q17*P17 -> 0
A18: 12 | B18: 46054 | C18: II | D18: =LEFT(E18,2) -> CG | E18: CG.03 | F18: FODG | G18: Gankesh | H18: Badriprasad Mali | I18: Pradip | J18: 200261 | K18: =VLOOKUP(J18,'[3]Item List (3)'!A$1:B$110000,2,FALSE) -> OR.211 YY4 | L18: 260116005 | M18: =IF((LEFT(J18))="2",$L$2,$J$2) -> OR | O18: =IFERROR(3600/N18,"") | P18: 1 | Q18: 3311 | S18: 13 | U18: =Q18+S18+T18 -> 3324 | V18: 180 | AQ18: 90 | BG18: =SUM(V18:BF18) -> 270 | BH18: =BG18/60 -> 4.5 | BI18: =IFERROR(BH18-SUM(W18:BF18)/60,0) -> 3 | BJ18: =IFERROR(BI18/BH18*100,0) -> 66.666667 | BK18: =IFERROR(((U18*N18)/(BI18*3600)*100),0) -> 0 | BL18: =IFERROR(((U18-(R18+S18+T18))/U18*100),0) -> 99.608905 | BM18: =IFERROR((((BJ18*BK18*BL18)/1000000)*100),0) -> 0 | BN18: =(W18+AP18+BE18+BF18)/60 -> 0 | BO18: =IFERROR(((BH18-BN18)*3600)/N18,0) -> 0 | BP18: =IFERROR(SUM(W18:BF18)/60-BN18,0) -> 1.5 | BQ18: =IFERROR(BP18*3600/N18,0) -> 0 | BW18: =Q18*P18 -> 3311
A19: 11 | B19: 46054 | C19: II | D19: =LEFT(E19,2) -> CG | E19: CG.03 | F19: RODG | G19: Gankesh | H19: Badriprasad Mali | I19: Pradip | J19: 208322.01 | K19: =VLOOKUP(J19,'[3]Item List (3)'!A$1:B$110000,2,FALSE) -> NA/RNA.OR 49/32 | M19: =IF((LEFT(J19))="2",$L$2,$J$2) -> OR | O19: =IFERROR(3600/N19,"") | P19: 2 | Q19: 2528 | U19: =Q19+S19+T19 -> 2528 | V19: 150 | W19: 120 | BG19: =SUM(V19:BF19) -> 270 | BH19: =BG19/60 -> 4.5 | BI19: =IFERROR(BH19-SUM(W19:BF19)/60,0) -> 2.5 | BJ19: =IFERROR(BI19/BH19*100,0) -> 55.555556 | BK19: =IFERROR(((U19*N19)/(BI19*3600)*100),0) -> 0 | BL19: =IFERROR(((U19-(R19+S19+T19))/U19*100),0) -> 100 | BM19: =IFERROR((((BJ19*BK19*BL19)/1000000)*100),0) -> 0 | BN19: =(W19+AP19+BE19+BF19)/60 -> 2 | BO19: =IFERROR(((BH19-BN19)*3600)/N19,0) -> 0 | BP19: =IFERROR(SUM(W19:BF19)/60-BN19,0) -> 0 | BQ19: =IFERROR(BP19*3600/N19,0) -> 0 | BW19: =Q19*P19 -> 5056
A20: 10 | B20: 46054 | C20: I | D20: =LEFT(E20,2) -> CG | E20: CG.04 | K20: =VLOOKUP(J20,'[3]Item List (3)'!A$1:B$110000,2,FALSE) -> #N/A | M20: =IF((LEFT(J20))="2",$L$2,$J$2) -> IR | O20: =IFERROR(3600/N20,"") | U20: =Q20+S20+T20 -> 0 | AX20: 480 | BG20: =SUM(V20:BF20) -> 480 | BH20: =BG20/60 -> 8 | BI20: =IFERROR(BH20-SUM(W20:BF20)/60,0) -> 0 | BJ20: =IFERROR(BI20/BH20*100,0) -> 0 | BK20: =IFERROR(((U20*N20)/(BI20*3600)*100),0) -> 0 | BL20: =IFERROR(((U20-(R20+S20+T20))/U20*100),0) -> 0 | BM20: =IFERROR((((BJ20*BK20*BL20)/1000000)*100),0) -> 0 | BN20: =(W20+AP20+BE20+BF20)/60 -> 0 | BO20: =IFERROR(((BH20-BN20)*3600)/N20,0) -> 0 | BP20: =IFERROR(SUM(W20:BF20)/60-BN20,0) -> 8 | BQ20: =IFERROR(BP20*3600/N20,0) -> 0 | BW20: =Q20*P20 -> 0
A21: 11 | B21: 46054 | C21: II | D21: =LEFT(E21,2) -> CG | E21: CG.04 | K21: =VLOOKUP(J21,'[3]Item List (3)'!A$1:B$110000,2,FALSE) -> #N/A | M21: =IF((LEFT(J21))="2",$L$2,$J$2) -> IR | O21: =IFERROR(3600/N21,"") | U21: =Q21+S21+T21 -> 0 | AX21: 480 | BG21: =SUM(V21:BF21) -> 480 | BH21: =BG21/60 -> 8 | BI21: =IFERROR(BH21-SUM(W21:BF21)/60,0) -> 0 | BJ21: =IFERROR(BI21/BH21*100,0) -> 0 | BK21: =IFERROR(((U21*N21)/(BI21*3600)*100),0) -> 0 | BL21: =IFERROR(((U21-(R21+S21+T21))/U21*100),0) -> 0 | BM21: =IFERROR((((BJ21*BK21*BL21)/1000000)*100),0) -> 0 | BN21: =(W21+AP21+BE21+BF21)/60 -> 0 | BO21: =IFERROR(((BH21-BN21)*3600)/N21,0) -> 0 | BP21: =IFERROR(SUM(W21:BF21)/60-BN21,0) -> 8 | BQ21: =IFERROR(BP21*3600/N21,0) -> 0 | BW21: =Q21*P21 -> 0
A22: 12 | B22: 46054 | C22: I | D22: =LEFT(E22,2) -> CG | E22: CG.09 | K22: =VLOOKUP(J22,'[3]Item List (3)'!A$1:B$110000,2,FALSE) -> #N/A | M22: =IF((LEFT(J22))="2",$L$2,$J$2) -> IR | O22: =IFERROR(3600/N22,"") | U22: =Q22+S22+T22 -> 0 | BG22: =SUM(V22:BF22) -> 0 | BH22: =BG22/60 -> 0 | BI22: =IFERROR(BH22-SUM(W22:BF22)/60,0) -> 0 | BJ22: =IFERROR(BI22/BH22*100,0) -> 0 | BK22: =IFERROR(((U22*N22)/(BI22*3600)*100),0) -> 0 | BL22: =IFERROR(((U22-(R22+S22+T22))/U22*100),0) -> 0 | BM22: =IFERROR((((BJ22*BK22*BL22)/1000000)*100),0) -> 0 | BN22: =(W22+AP22+BE22+BF22)/60 -> 0 | BO22: =IFERROR(((BH22-BN22)*3600)/N22,0) -> 0 | BP22: =IFERROR(SUM(W22:BF22)/60-BN22,0) -> 0 | BQ22: =IFERROR(BP22*3600/N22,0) -> 0 | BW22: =Q22*P22 -> 0
A23: 13 | B23: 46054 | C23: II | D23: =LEFT(E23,2) -> CG | E23: CG.09 | K23: =VLOOKUP(J23,'[3]Item List (3)'!A$1:B$110000,2,FALSE) -> #N/A | M23: =IF((LEFT(J23))="2",$L$2,$J$2) -> IR | O23: =IFERROR(3600/N23,"") | U23: =Q23+S23+T23 -> 0 | BG23: =SUM(V23:BF23) -> 0 | BH23: =BG23/60 -> 0 | BI23: =IFERROR(BH23-SUM(W23:BF23)/60,0) -> 0 | BJ23: =IFERROR(BI23/BH23*100,0) -> 0 | BK23: =IFERROR(((U23*N23)/(BI23*3600)*100),0) -> 0 | BL23: =IFERROR(((U23-(R23+S23+T23))/U23*100),0) -> 0 | BM23: =IFERROR((((BJ23*BK23*BL23)/1000000)*100),0) -> 0 | BN23: =(W23+AP23+BE23+BF23)/60 -> 0 | BO23: =IFERROR(((BH23-BN23)*3600)/N23,0) -> 0 | BP23: =IFERROR(SUM(W23:BF23)/60-BN23,0) -> 0 | BQ23: =IFERROR(BP23*3600/N23,0) -> 0 | BW23: =Q23*P23 -> 0
A24: 17 | B24: 46054 | C24: I | D24: =LEFT(E24,2) -> EG | E24: EG.02 | K24: =VLOOKUP(J24,'[3]Item List (3)'!A$1:B$110000,2,FALSE) -> #N/A | M24: =IF((LEFT(J24))="2",$L$2,$J$2) -> IR | O24: =IFERROR(3600/N24,"") | U24: =Q24+S24+T24 -> 0 | AR24: 480 | BG24: =SUM(V24:BF24) -> 480 | BH24: =BG24/60 -> 8 | BI24: =IFERROR(BH24-SUM(W24:BF24)/60,0) -> 0 | BJ24: =IFERROR(BI24/BH24*100,0) -> 0 | BK24: =IFERROR(((U24*N24)/(BI24*3600)*100),0) -> 0 | BL24: =IFERROR(((U24-(R24+S24+T24))/U24*100),0) -> 0 | BM24: =IFERROR((((BJ24*BK24*BL24)/1000000)*100),0) -> 0 | BN24: =(W24+AP24+BE24+BF24)/60 -> 0 | BO24: =IFERROR(((BH24-BN24)*3600)/N24,0) -> 0 | BP24: =IFERROR(SUM(W24:BF24)/60-BN24,0) -> 8 | BQ24: =IFERROR(BP24*3600/N24,0) -> 0 | BW24: =Q24*P24 -> 0
A25: 20 | B25: 46054 | C25: II | D25: =LEFT(E25,2) -> EG | E25: EG.02 | K25: =VLOOKUP(J25,'[3]Item List (3)'!A$1:B$110000,2,FALSE) -> #N/A | M25: =IF((LEFT(J25))="2",$L$2,$J$2) -> IR | O25: =IFERROR(3600/N25,"") | U25: =Q25+S25+T25 -> 0 | BF25: 480 | BG25: =SUM(V25:BF25) -> 480 | BH25: =BG25/60 -> 8 | BI25: =IFERROR(BH25-SUM(W25:BF25)/60,0) -> 0 | BJ25: =IFERROR(BI25/BH25*100,0) -> 0 | BK25: =IFERROR(((U25*N25)/(BI25*3600)*100),0) -> 0 | BL25: =IFERROR(((U25-(R25+S25+T25))/U25*100),0) -> 0 | BM25: =IFERROR((((BJ25*BK25*BL25)/1000000)*100),0) -> 0 | BN25: =(W25+AP25+BE25+BF25)/60 -> 8 | BO25: =IFERROR(((BH25-BN25)*3600)/N25,0) -> 0 | BP25: =IFERROR(SUM(W25:BF25)/60-BN25,0) -> 0 | BQ25: =IFERROR(BP25*3600/N25,0) -> 0 | BW25: =Q25*P25 -> 0
A26: 21 | B26: 46054 | C26: I | D26: =LEFT(E26,2) -> EG | E26: EG.04 | F26: CODG | G26: Dilip Panday | J26: 208281 | K26: =VLOOKUP(J26,'[3]Item List (3)'!A$1:B$110000,2,FALSE) -> D.OR 14536 | M26: =IF((LEFT(J26))="2",$L$2,$J$2) -> OR | N26: 45 | O26: =IFERROR(3600/N26,"") -> 80 | P26: 1 | Q26: 145 | R26: 9 | S26: 1 | U26: =Q26+S26+T26 -> 146 | V26: 150 | W26: 120 | AR26: 330 | BG26: =SUM(V26:BF26) -> 600 | BH26: =BG26/60 -> 10 | BI26: =IFERROR(BH26-SUM(W26:BF26)/60,0) -> 2.5 | BJ26: =IFERROR(BI26/BH26*100,0) -> 25 | BK26: =IFERROR(((U26*N26)/(BI26*3600)*100),0) -> 73 | BL26: =IFERROR(((U26-(R26+S26+T26))/U26*100),0) -> 93.150685 | BM26: =IFERROR((((BJ26*BK26*BL26)/1000000)*100),0) -> 17 | BN26: =(W26+AP26+BE26+BF26)/60 -> 2 | BO26: =IFERROR(((BH26-BN26)*3600)/N26,0) -> 640 | BP26: =IFERROR(SUM(W26:BF26)/60-BN26,0) -> 5.5 | BQ26: =IFERROR(BP26*3600/N26,0) -> 440 | BW26: =Q26*P26 -> 145
A27: 22 | B27: 46054 | C27: II | D27: =LEFT(E27,2) -> EG | E27: EG.04 | F27: CODG | G27: Jaglal Gupta | J27: 202103 | K27: =VLOOKUP(J27,'[3]Item List (3)'!A$1:B$110000,2,FALSE) -> #N/A | M27: =IF((LEFT(J27))="2",$L$2,$J$2) -> OR | N27: 40 | O27: =IFERROR(3600/N27,"") -> 90 | P27: 1 | Q27: 26 | R27: 4 | U27: =Q27+S27+T27 -> 26 | V27: 30 | W27: 60 | AR27: 390 | BG27: =SUM(V27:BF27) -> 480 | BH27: =BG27/60 -> 8 | BI27: =IFERROR(BH27-SUM(W27:BF27)/60,0) -> 0.5 | BJ27: =IFERROR(BI27/BH27*100,0) -> 6.25 | BK27: =IFERROR(((U27*N27)/(BI27*3600)*100),0) -> 57.777778 | BL27: =IFERROR(((U27-(R27+S27+T27))/U27*100),0) -> 84.615385 | BM27: =IFERROR((((BJ27*BK27*BL27)/1000000)*100),0) -> 3.0555556 | BN27: =(W27+AP27+BE27+BF27)/60 -> 1 | BO27: =IFERROR(((BH27-BN27)*3600)/N27,0) -> 630 | BP27: =IFERROR(SUM(W27:BF27)/60-BN27,0) -> 6.5 | BQ27: =IFERROR(BP27*3600/N27,0) -> 585 | BW27: =Q27*P27 -> 26
A28: 23 | B28: 46054 | C28: I | D28: =LEFT(E28,2) -> EG | E28: EG.05 | F28: CODG | G28: Kiran Vaghadiya | J28: 208281 | K28: =VLOOKUP(J28,'[3]Item List (3)'!A$1:B$110000,2,FALSE) -> D.OR 14536 | L28: 251225006 | M28: =IF((LEFT(J28))="2",$L$2,$J$2) -> OR | N28: 50 | O28: =IFERROR(3600/N28,"") -> 72 | P28: 1 | Q28: 200 | R28: 6 | S28: 2 | U28: =Q28+S28+T28 -> 202 | V28: 210 | W28: 60 | X28: 30 | AR28: 180 | BG28: =SUM(V28:BF28) -> 480 | BH28: =BG28/60 -> 8 | BI28: =IFERROR(BH28-SUM(W28:BF28)/60,0) -> 3.5 | BJ28: =IFERROR(BI28/BH28*100,0) -> 43.75 | BK28: =IFERROR(((U28*N28)/(BI28*3600)*100),0) -> 80.15873 | BL28: =IFERROR(((U28-(R28+S28+T28))/U28*100),0) -> 96.039604 | BM28: =IFERROR((((BJ28*BK28*BL28)/1000000)*100),0) -> 33.680556 | BN28: =(W28+AP28+BE28+BF28)/60 -> 1 | BO28: =IFERROR(((BH28-BN28)*3600)/N28,0) -> 504 | BP28: =IFERROR(SUM(W28:BF28)/60-BN28,0) -> 3.5 | BQ28: =IFERROR(BP28*3600/N28,0) -> 252 | BW28: =Q28*P28 -> 200
A29: 26 | B29: 46054 | C29: II | D29: =LEFT(E29,2) -> EG | E29: EG.05 | F29: CODG | G29: Kiran Vaghadiya | H29: Jaglal Gupta | I29: Anand | J29: 208281 | K29: =VLOOKUP(J29,'[3]Item List (3)'!A$1:B$110000,2,FALSE) -> D.OR 14536 | L29: 251225006 | M29: =IF((LEFT(J29))="2",$L$2,$J$2) -> OR | N29: 50 | O29: =IFERROR(3600/N29,"") -> 72 | P29: 1 | Q29: 282 | R29: 17 | S29: 7 | U29: =Q29+S29+T29 -> 289 | V29: 360 | X29: 120 | BG29: =SUM(V29:BF29) -> 480 | BH29: =BG29/60 -> 8 | BI29: =IFERROR(BH29-SUM(W29:BF29)/60,0) -> 6 | BJ29: =IFERROR(BI29/BH29*100,0) -> 75 | BK29: =IFERROR(((U29*N29)/(BI29*3600)*100),0) -> 66.898148 | BL29: =IFERROR(((U29-(R29+S29+T29))/U29*100),0) -> 91.695502 | BM29: =IFERROR((((BJ29*BK29*BL29)/1000000)*100),0) -> 46.006944 | BN29: =(W29+AP29+BE29+BF29)/60 -> 0 | BO29: =IFERROR(((BH29-BN29)*3600)/N29,0) -> 576 | BP29: =IFERROR(SUM(W29:BF29)/60-BN29,0) -> 2 | BQ29: =IFERROR(BP29*3600/N29,0) -> 144 | BW29: =Q29*P29 -> 282
A30: 27 | B30: 46054 | C30: I | D30: =LEFT(E30,2) -> EG | E30: EG.07 | F30: TG | G30: Shrawan Matho | H30: Jaglal Gupta | J30: 100261 | K30: =VLOOKUP(J30,'[3]Item List (3)'!A$1:B$110000,2,FALSE) -> IR. 211 YY4 | L30: 260116004 | M30: =IF((LEFT(J30))="2",$L$2,$J$2) -> IR | N30: 20 | O30: =IFERROR(3600/N30,"") -> 180 | P30: 1 | Q30: 1040 | R30: 3 | S30: 2 | U30: =Q30+S30+T30 -> 1042 | V30: 360 | AP30: 60 | BC30: 60 | BG30: =SUM(V30:BF30) -> 480 | BH30: =BG30/60 -> 8 | BI30: =IFERROR(BH30-SUM(W30:BF30)/60,0) -> 6 | BJ30: =IFERROR(BI30/BH30*100,0) -> 75 | BK30: =IFERROR(((U30*N30)/(BI30*3600)*100),0) -> 96.481481 | BL30: =IFERROR(((U30-(R30+S30+T30))/U30*100),0) -> 99.520154 | BM30: =IFERROR((((BJ30*BK30*BL30)/1000000)*100),0) -> 72.013889 | BN30: =(W30+AP30+BE30+BF30)/60 -> 1 | BO30: =IFERROR(((BH30-BN30)*3600)/N30,0) -> 1260 | BP30: =IFERROR(SUM(W30:BF30)/60-BN30,0) -> 1 | BQ30: =IFERROR(BP30*3600/N30,0) -> 180 | BW30: =Q30*P30 -> 1040
A31: 28 | B31: 46054 | C31: II | D31: =LEFT(E31,2) -> EG | E31: EG.07 | F31: TG | G31: Jaglal Gupta | H31: Kiran Vaghadiya | J31: 100261 | K31: =VLOOKUP(J31,'[3]Item List (3)'!A$1:B$110000,2,FALSE) -> IR. 211 YY4 | L31: 260116004 | M31: =IF((LEFT(J31))="2",$L$2,$J$2) -> IR | N31: 20 | O31: =IFERROR(3600/N31,"") -> 180 | P31: 1 | Q31: 441 | U31: =Q31+S31+T31 -> 441 | V31: 150 | AN31: 30 | AR31: 300 | BG31: =SUM(V31:BF31) -> 480 | BH31: =BG31/60 -> 8 | BI31: =IFERROR(BH31-SUM(W31:BF31)/60,0) -> 2.5 | BJ31: =IFERROR(BI31/BH31*100,0) -> 31.25 | BK31: =IFERROR(((U31*N31)/(BI31*3600)*100),0) -> 98 | BL31: =IFERROR(((U31-(R31+S31+T31))/U31*100),0) -> 100 | BM31: =IFERROR((((BJ31*BK31*BL31)/1000000)*100),0) -> 30.625 | BN31: =(W31+AP31+BE31+BF31)/60 -> 0 | BO31: =IFERROR(((BH31-BN31)*3600)/N31,0) -> 1440 | BP31: =IFERROR(SUM(W31:BF31)/60-BN31,0) -> 5.5 | BQ31: =IFERROR(BP31*3600/N31,0) -> 990 | BW31: =Q31*P31 -> 441
A32: 29 | B32: 46054 | C32: I | D32: =LEFT(E32,2) -> EG | E32: EG.08 | K32: =VLOOKUP(J32,'[3]Item List (3)'!A$1:B$110000,2,FALSE) -> #N/A | M32: =IF((LEFT(J32))="2",$L$2,$J$2) -> IR | O32: =IFERROR(3600/N32,"") | U32: =Q32+S32+T32 -> 0 | BG32: =SUM(V32:BF32) -> 0 | BH32: =BG32/60 -> 0 | BI32: =IFERROR(BH32-SUM(W32:BF32)/60,0) -> 0 | BJ32: =IFERROR(BI32/BH32*100,0) -> 0 | BK32: =IFERROR(((U32*N32)/(BI32*3600)*100),0) -> 0 | BL32: =IFERROR(((U32-(R32+S32+T32))/U32*100),0) -> 0 | BM32: =IFERROR((((BJ32*BK32*BL32)/1000000)*100),0) -> 0 | BN32: =(W32+AP32+BE32+BF32)/60 -> 0 | BO32: =IFERROR(((BH32-BN32)*3600)/N32,0) -> 0 | BP32: =IFERROR(SUM(W32:BF32)/60-BN32,0) -> 0 | BQ32: =IFERROR(BP32*3600/N32,0) -> 0 | BW32: =Q32*P32 -> 0
A33: 30 | B33: 46054 | C33: II | D33: =LEFT(E33,2) -> EG | E33: EG.08 | K33: =VLOOKUP(J33,'[3]Item List (3)'!A$1:B$110000,2,FALSE) -> #N/A | M33: =IF((LEFT(J33))="2",$L$2,$J$2) -> IR | O33: =IFERROR(3600/N33,"") | U33: =Q33+S33+T33 -> 0 | BG33: =SUM(V33:BF33) -> 0 | BH33: =BG33/60 -> 0 | BI33: =IFERROR(BH33-SUM(W33:BF33)/60,0) -> 0 | BJ33: =IFERROR(BI33/BH33*100,0) -> 0 | BK33: =IFERROR(((U33*N33)/(BI33*3600)*100),0) -> 0 | BL33: =IFERROR(((U33-(R33+S33+T33))/U33*100),0) -> 0 | BM33: =IFERROR((((BJ33*BK33*BL33)/1000000)*100),0) -> 0 | BN33: =(W33+AP33+BE33+BF33)/60 -> 0 | BO33: =IFERROR(((BH33-BN33)*3600)/N33,0) -> 0 | BP33: =IFERROR(SUM(W33:BF33)/60-BN33,0) -> 0 | BQ33: =IFERROR(BP33*3600/N33,0) -> 0 | BW33: =Q33*P33 -> 0
A34: 31 | B34: 46054 | C34: I | D34: =LEFT(E34,2) -> IG | E34: IG.01 | K34: =VLOOKUP(J34,'[3]Item List (3)'!A$1:B$110000,2,FALSE) -> #N/A | M34: =IF((LEFT(J34))="2",$L$2,$J$2) -> IR | O34: =IFERROR(3600/N34,"") | U34: =Q34+S34+T34 -> 0 | AU34: 480 | BG34: =SUM(V34:BF34) -> 480 | BH34: =BG34/60 -> 8 | BI34: =IFERROR(BH34-SUM(W34:BF34)/60,0) -> 0 | BJ34: =IFERROR(BI34/BH34*100,0) -> 0 | BK34: =IFERROR(((U34*N34)/(BI34*3600)*100),0) -> 0 | BL34: =IFERROR(((U34-(R34+S34+T34))/U34*100),0) -> 0 | BM34: =IFERROR((((BJ34*BK34*BL34)/1000000)*100),0) -> 0 | BN34: =(W34+AP34+BE34+BF34)/60 -> 0 | BO34: =IFERROR(((BH34-BN34)*3600)/N34,0) -> 0 | BP34: =IFERROR(SUM(W34:BF34)/60-BN34,0) -> 8 | BQ34: =IFERROR(BP34*3600/N34,0) -> 0 | BW34: =Q34*P34 -> 0
A35: 32 | B35: 46054 | C35: II | D35: =LEFT(E35,2) -> IG | E35: IG.01 | K35: =VLOOKUP(J35,'[3]Item List (3)'!A$1:B$110000,2,FALSE) -> #N/A | M35: =IF((LEFT(J35))="2",$L$2,$J$2) -> IR | O35: =IFERROR(3600/N35,"") | U35: =Q35+S35+T35 -> 0 | AU35: 480 | BG35: =SUM(V35:BF35) -> 480 | BH35: =BG35/60 -> 8 | BI35: =IFERROR(BH35-SUM(W35:BF35)/60,0) -> 0 | BJ35: =IFERROR(BI35/BH35*100,0) -> 0 | BK35: =IFERROR(((U35*N35)/(BI35*3600)*100),0) -> 0 | BL35: =IFERROR(((U35-(R35+S35+T35))/U35*100),0) -> 0 | BM35: =IFERROR((((BJ35*BK35*BL35)/1000000)*100),0) -> 0 | BN35: =(W35+AP35+BE35+BF35)/60 -> 0 | BO35: =IFERROR(((BH35-BN35)*3600)/N35,0) -> 0 | BP35: =IFERROR(SUM(W35:BF35)/60-BN35,0) -> 8 | BQ35: =IFERROR(BP35*3600/N35,0) -> 0 | BW35: =Q35*P35 -> 0
A36: 32 | B36: 46054 | C36: I | D36: =LEFT(E36,2) -> IG | E36: IG.04 | F36: BG | G36: Vala Himesh | H36: Shrawan Matho | J36: 104332.01 | K36: =VLOOKUP(J36,'[3]Item List (3)'!A$1:B$110000,2,FALSE) -> NA/RNA.IR 6908 | L36: 251012002 | M36: =IF((LEFT(J36))="2",$L$2,$J$2) -> IR | N36: 45 | O36: =IFERROR(3600/N36,"") -> 80 | P36: 1 | Q36: 4 | R36: 45 | S36: 8 | U36: =Q36+S36+T36 -> 12 | V36: 60 | W36: 120 | AR36: 300 | BG36: =SUM(V36:BF36) -> 480 | BH36: =BG36/60 -> 8 | BI36: =IFERROR(BH36-SUM(W36:BF36)/60,0) -> 1 | BJ36: =IFERROR(BI36/BH36*100,0) -> 12.5 | BK36: =IFERROR(((U36*N36)/(BI36*3600)*100),0) -> 15 | BL36: =IFERROR(((U36-(R36+S36+T36))/U36*100),0) -> -341.66667 | BM36: =IFERROR((((BJ36*BK36*BL36)/1000000)*100),0) -> -6.40625 | BN36: =(W36+AP36+BE36+BF36)/60 -> 2 | BO36: =IFERROR(((BH36-BN36)*3600)/N36,0) -> 480 | BP36: =IFERROR(SUM(W36:BF36)/60-BN36,0) -> 5 | BQ36: =IFERROR(BP36*3600/N36,0) -> 400 | BW36: =Q36*P36 -> 4
A37: 35 | B37: 46054 | C37: II | D37: =LEFT(E37,2) -> IG | E37: IG.04 | F37: BG | G37: Raymalbhai Bharathiya | J37: 104332.01 | K37: =VLOOKUP(J37,'[3]Item List (3)'!A$1:B$110000,2,FALSE) -> NA/RNA.IR 6908 | L37: 251012002 | M37: =IF((LEFT(J37))="2",$L$2,$J$2) -> IR | N37: 45 | O37: =IFERROR(3600/N37,"") -> 80 | P37: 1 | Q37: 232 | R37: 43 | S37: 15 | U37: =Q37+S37+T37 -> 247 | V37: 285 | X37: 20 | Z37: 100 | AC37: 30 | AP37: 30 | BC37: 10 | BE37: 5 | BG37: =SUM(V37:BF37) -> 480 | BH37: =BG37/60 -> 8 | BI37: =IFERROR(BH37-SUM(W37:BF37)/60,0) -> 4.75 | BJ37: =IFERROR(BI37/BH37*100,0) -> 59.375 | BK37: =IFERROR(((U37*N37)/(BI37*3600)*100),0) -> 65 | BL37: =IFERROR(((U37-(R37+S37+T37))/U37*100),0) -> 76.518219 | BM37: =IFERROR((((BJ37*BK37*BL37)/1000000)*100),0) -> 29.53125 | BN37: =(W37+AP37+BE37+BF37)/60 -> 0.58333333 | BO37: =IFERROR(((BH37-BN37)*3600)/N37,0) -> 593.33333 | BP37: =IFERROR(SUM(W37:BF37)/60-BN37,0) -> 2.6666667 | BQ37: =IFERROR(BP37*3600/N37,0) -> 213.33333 | BW37: =Q37*P37 -> 232
A38: 36 | B38: 46054 | C38: I | D38: =LEFT(E38,2) -> IG | E38: IG.11 | K38: =VLOOKUP(J38,'[3]Item List (3)'!A$1:B$110000,2,FALSE) -> #N/A | M38: =IF((LEFT(J38))="2",$L$2,$J$2) -> IR | O38: =IFERROR(3600/N38,"") | U38: =Q38+S38+T38 -> 0 | AR38: 480 | BG38: =SUM(V38:BF38) -> 480 | BH38: =BG38/60 -> 8 | BI38: =IFERROR(BH38-SUM(W38:BF38)/60,0) -> 0 | BJ38: =IFERROR(BI38/BH38*100,0) -> 0 | BK38: =IFERROR(((U38*N38)/(BI38*3600)*100),0) -> 0 | BL38: =IFERROR(((U38-(R38+S38+T38))/U38*100),0) -> 0 | BM38: =IFERROR((((BJ38*BK38*BL38)/1000000)*100),0) -> 0 | BN38: =(W38+AP38+BE38+BF38)/60 -> 0 | BO38: =IFERROR(((BH38-BN38)*3600)/N38,0) -> 0 | BP38: =IFERROR(SUM(W38:BF38)/60-BN38,0) -> 8 | BQ38: =IFERROR(BP38*3600/N38,0) -> 0 | BW38: =Q38*P38 -> 0
A39: 44 | B39: 46054 | C39: II | D39: =LEFT(E39,2) -> IG | E39: IG.11 | K39: =VLOOKUP(J39,'[3]Item List (3)'!A$1:B$110000,2,FALSE) -> #N/A | M39: =IF((LEFT(J39))="2",$L$2,$J$2) -> IR | O39: =IFERROR(3600/N39,"") | U39: =Q39+S39+T39 -> 0 | BF39: 480 | BG39: =SUM(V39:BF39) -> 480 | BH39: =BG39/60 -> 8 | BI39: =IFERROR(BH39-SUM(W39:BF39)/60,0) -> 0 | BJ39: =IFERROR(BI39/BH39*100,0) -> 0 | BK39: =IFERROR(((U39*N39)/(BI39*3600)*100),0) -> 0 | BL39: =IFERROR(((U39-(R39+S39+T39))/U39*100),0) -> 0 | BM39: =IFERROR((((BJ39*BK39*BL39)/1000000)*100),0) -> 0 | BN39: =(W39+AP39+BE39+BF39)/60 -> 8 | BO39: =IFERROR(((BH39-BN39)*3600)/N39,0) -> 0 | BP39: =IFERROR(SUM(W39:BF39)/60-BN39,0) -> 0 | BQ39: =IFERROR(BP39*3600/N39,0) -> 0 | BW39: =Q39*P39 -> 0
A40: 45 | B40: 46054 | C40: I | D40: =LEFT(E40,2) -> IG | E40: IG.12 | K40: =VLOOKUP(J40,'[3]Item List (3)'!A$1:B$110000,2,FALSE) -> #N/A | M40: =IF((LEFT(J40))="2",$L$2,$J$2) -> IR | O40: =IFERROR(3600/N40,"") | U40: =Q40+S40+T40 -> 0 | AR40: 480 | BG40: =SUM(V40:BF40) -> 480 | BH40: =BG40/60 -> 8 | BI40: =IFERROR(BH40-SUM(W40:BF40)/60,0) -> 0 | BJ40: =IFERROR(BI40/BH40*100,0) -> 0 | BK40: =IFERROR(((U40*N40)/(BI40*3600)*100),0) -> 0 | BL40: =IFERROR(((U40-(R40+S40+T40))/U40*100),0) -> 0 | BM40: =IFERROR((((BJ40*BK40*BL40)/1000000)*100),0) -> 0 | BN40: =(W40+AP40+BE40+BF40)/60 -> 0 | BO40: =IFERROR(((BH40-BN40)*3600)/N40,0) -> 0 | BP40: =IFERROR(SUM(W40:BF40)/60-BN40,0) -> 8 | BQ40: =IFERROR(BP40*3600/N40,0) -> 0 | BW40: =Q40*P40 -> 0
...

Sheet Cp - Cpk
A10: Cp_Cpk Summary Sheet
A11: Machine | B11: 46054 | C11: 46055 | D11: 46056 | E11: 46057 | F11: 46058 | G11: 46059 | H11: 46060 | I11: 46061 | J11: 46062 | K11: 46063 | L11: 46064 | M11: 46065 | N11: 46066 | O11: 46067 | P11: 46068 | Q11: 46069 | R11: 46070 | S11: 46071 | T11: 46072 | U11: 46073 | V11: 46074 | W11: 46075 | X11: 46076 | Y11: 46077 | Z11: 46078 | AA11: 46079 | AB11: 46080 | AC11: 46081 | AD11: {=AVERAGE() | AG11: {=AVERAGE()
A12: IG.01 | P12: 1.59 | AC12: 1.53 | AD12: =AVERAGE(B12:AC12) -> 1.56
A13: IG.04 | F13: 1.17 | O13: 0.99 | AD13: =AVERAGE(B13:AC13) -> 1.08
A14: IG.11 | D14: 1.15 | E14: 2.29 | H14: 1.2 | Q14: 1.16 | AD14: =AVERAGE(B14:AC14) -> 1.45
A15: IG.12 | N15: 0.42 | AD15: =AVERAGE(B15:AC15) -> 0.42
A16: IG.13 | AD16: =AVERAGE(B16:AC16) -> #DIV/0!
A17: IG.14 | AD17: =AVERAGE(B17:AC17) -> #DIV/0!
A18: IG.15 | C18: 1.24 | H18: 1.18 | R18: 1.43 | Y18: 1.11 | AD18: =AVERAGE(B18:AC18) -> 1.24
A19: IG.16 | I19: 1.01 | R19: 1.51 | AD19: =AVERAGE(B19:AC19) -> 1.26
A20: IG.17 | F20: 1.02 | Y20: 1.13 | AD20: =AVERAGE(B20:AC20) -> 1.075
A21: IG.18 | D21: 1.52 | I21: 1.26 | R21: 1.2 | AD21: =AVERAGE(B21:AC21) -> 1.3266667

Sheet BOM
A1: Item Code | B1: Item Name
A2: c | B2: BR 2800 (F)
A3: 1.05 | B3: BR CLIPS 2800 (F)
A4: 1.06 | B4: NCG 2800 (F)
A5: 1.1 | B5: BR 2800 (TCG) (F)
A6: 10 | B6: BR 282423XC (F)
A7: 100 | B7: BR 3017(26) (F)
A8: 100.02 | B8: IR BR 3017(26) (F)
A9: 100.05 | B9: BR CLIPS 3017(26) (F)
A10: 100.15 | B10: BR 3017(26) I.D.P (F)
A11: 100006 | B11: SHAFT10X74 (G)
A12: 100007 | B12: SHAFT10X42 (G)
A13: 100009 | B13: SHAFT 6X21.8 (P)
A14: 100040.01 | B14: IR.MBT2830EGL (G)
... A86: 1009 | B86: 001 0930041746(4920084) (F)
A87: 100930 | B87: 220315004
A88: 100931 | B88: G.IR 1103 KRRB (T)
A89: 100932 | B89: G.IR 1107 KRRB (G)
A90: 100933 | B90: G.IR 1115 KRRB (T)
A91: 100934 | B91: G.IR 1203 KRRB (G)
A92: 100935 | B92: UC.IR 211 (T)
A93: 100937 | B93: UC.IR 211_60X110 (G)
A94: 100946.03 | B94: IR.IR 28X32X17 (T)
A95: 1010 | B95: 0020 940042650(4910203) (F)
A96: 101001 | B96: MCFR.STADE 90 S (P)
A97: 101001.01 | B97: MFCR.WASHER 90 S (T)
A98: 101003.31 | B98: 85MM LENGTH LINK (G)
A99: 101003.32 | B99: 98MM LENGTH LINK (T)
... A1884: 1421002 | B1884: PIN 7PG16L
A1885: 1421003 | B1885: 4920892
A1886: 1421003 | B1886: 4920893
A1887: 1421003 | B1887: 4920894
A1888: 1421003 | B1888: 4920897 WASHER
A1889: 1421003.2 | B1889: 4920893 SPL
A1890: 1421003.3 | B1890: 245GOSP SCISSORASSLY mate
A1891: 1421003.3 | B1891: 491306 LINK
A1892: 1421003.3 | B1892: Simens circlip
A1893: 1421004 | B1893: 940041770 material
A1894: 1421007 | B1894: 940041790 material
A1895: 1421008 | B1895: 940041795 material
...

Sheet Backend Data for KPI
A6: Production Planning And Achievement Summary Sheet Day Wise Jan-2025 | G6: Downtime & Loss Qty.
A7: M/c2 | B7: Sum of M/C Plan Qty. | C7: Sum of Good | D7: Sum of Rework | E7: Sum of IN Running REJ. | F7: Sum of Total | G7: Sum of Down Time (Hrs) | H7: Sum of Total Loss Qty.
A8: IG.01 | B8: 21782.609 | C8: 17764 | D8: 91 | E8: 227 | F8: 18038 | G8: 52.916667 | H8: 3273.913
A9: IG.04 | B9: 14392.381 | C9: 6935 | D9: 631 | E9: 311 | F9: 7270 | G9: 59.333333 | H9: 4771.4286
A10: IG.12 | B10: 0 | F10: 0 | G10: 24 | H10: 0
A11: IG.13 | B11: 10663 | C11: 6216 | D11: 299 | E11: 59 | F11: 6272 | G11: 35 | H11: 2697.6667
A12: IG.14 | B12: 19332 | C12: 14735 | D12: 214 | E12: 75 | F12: 14841 | G12: 48.166667 | H12: 2634
A13: IG.15 | B13: 20424 | C13: 13003 | D13: 1092 | E13: 462 | F13: 13829 | G13: 16 | H13: 2064
A14: IG.16 | B14: 19512 | C14: 15800 | D14: 72 | E14: 210 | F14: 16017 | G14: 12.416667 | H14: 1469
A15: IG.17 | B15: 2373.3333 | C15: 1018 | D15: 64 | E15: 4 | F15: 1022 | G15: 106.08333 | H15: 913.33333
A16: IG.18 | B16: 17660 | C16: 10500 | D16: 388 | E16: 309 | F16: 10809 | G16: 37.083333 | H16: 4450
A17: IG.11 | B17: 12843.447 | C17: 7188 | D17: 399 | E17: 374 | F17: 7569 | G17: 51.75 | H17: 2779.5963
A18: IG.19 | B18: 940 | C18: 314 | D18: 52 | E18: 10 | F18: 325 | G18: 91.25 | H18: 450
A19: IG.20 | B19: 6580 | C19: 2487 | D19: 145 | E19: 57 | F19: 2557 | G19: 71.333333 | H19: 2800
A20: Grand Total | B20: 146502.77 | C20: 95960 | D20: 3447 | E20: 2098 | F20: 98549 | G20: 605.33333 | H20: 28302.938
D22: All Data Are In Minute
D23: M/c2 | E23: Sum of RE SETTING,LODING | F23: Sum of Ovality Problem 11Ov | G23: Sum of Taper Problem 11Tp | H23: Sum of Ra Problem 11Ra | I23: Sum of Raadiua Problem 11Rd | J23: Sum of Size variation Problem 11 Sv IPG Pro | K23: Sum of Diamond Turn 11Dt | L23: Sum of Diamond change 11Dc | M23: Sum of Tool Waiting 12 | N23: Sum of Finishing Problem 11Fn | O23: Sum of No Operator 13 | P23: Sum of No Power 24 | Q23: Sum of Mech.Maint.21 | R23: Sum of Elec. Maint. 22 | S23: Sum of Other 27
A24: Ach. % | B24: =GETPIVOTDATA("Sum of Total",$A$7)*100/GETPIVOTDATA("Sum of M/C Plan Qty.",$A$7) -> 67.26767 | D24: IG.01 | E24: 600 | G24: 35 | J24: 30 | K24: 15 | P24: 45 | Q24: 120 | R24: 30
D25: IG.04 | E25: 605 | F25: 20 | G25: 565 | J25: 210 | K25: 30 | L25: 10 | M25: 60 | O25: 770 | P25: 60 | Q25: 20 | R25: 130 | S25: 150
D26: IG.12 | O26: 480
A27: Efficiency Loss % | B27: =B30*100/GETPIVOTDATA("Sum of M/C Plan Qty.",$A$7) -> 13.413284 | D27: IG.13 | E27: 20 | F27: 15 | G27: 105 | K27: 25 | L27: 10 | O27: 1580 | P27: 85 | R27: 10 | S27: 10
D28: IG.14 | O28: 60 | P28: 45 | R28: 145 | S28: 35
D29: IG.15 | E29: 175 | F29: 80 | G29: 95 | J29: 70 | K29: 135 | O29: 60 | P29: 130 | S29: 185
A30: =GETPIVOTDATA("Sum of Total",$A$7)+GETPIVOTDATA("Sum of Total Loss Qty.",$A$7) -> 126851.94 | B30: =GETPIVOTDATA("Sum of M/C Plan Qty.",$A$7)-A30 -> 19650.832 | D30: IG.16 | E30: 40 | G30: 60 | J30: 45 | K30: 100 | L30: 15 | O30: 150 | P30: 130 | S30: 130
A31: Down Time Loss Qty. % | B31: =GETPIVOTDATA("Sum of Total Loss Qty.",$A$7)*100/GETPIVOTDATA("Sum of M/C Plan Qty.",$A$7) -> 19.319046 | D31: IG.17 | K31: 25 | O31: 3960 | P31: 60 | Q31: 1920 | S31: 40
D32: IG.18 | E32: 170 | F32: 40 | G32: 150 | H32: 10 | J32: 160 | K32: 85 | L32: 20 | O32: 1290 | P32: 145 | R32: 15 | S32: 90
D33: IG.11 | E33: 305 | F33: 45 | G33: 75 | J33: 210 | K33: 85 | M33: 30 | O33: 1560 | P33: 115 | Q33: 70 | R33: 10 | S33: 100
D34: IG.19 | E34: 70 | O34: 1890 | R34: 155
D35: IG.20 | E35: 280 | G35: 35 | O35: 3385 | P35: 100
D36: Grand Total | E36: 2265 | F36: 200 | G36: 1120 | H36: 10 | J36: 725 | K36: 500 | L36: 55 | M36: 90 | O36: 15185 | P36: 915 | Q36: 2130 | R36: 495 | S36: 740
B38: =
A41: IG Machine PPM Rew+Rej+TR Average | E41: IG | G41: =AVERAGE(G43:G73) -> 36255.989 | H41: =AVERAGE(H43:H73) -> 21360.911 | I41: =AVERAGE(I43:I73) -> 4612.8144 | K41: EG PPM Rew+Rej+TR Average | O41: EG | Q41: =AVERAGE(Q43:Q73) -> 7637.6717 | R41: =AVERAGE(R43:R73) -> 1939.1249 | S41: =AVERAGE(S43:S73) -> 130.69114 | U41: FG Machine PPM Rew+Rej+TR Average | Y41: FG | AA41: =AVERAGE(AA43:AA73) -> 0 | AB41: =AVERAGE(AB43:AB73) -> 162.06743 | AC41: =AVERAGE(AC43:AC73) -> 4.9775017 | AI41: CG | AK41: =AVERAGE(AK43:AK73) -> #DIV/0! | AL41: =AVERAGE(AL43:AL73) -> #DIV/0! | AM41: =AVERAGE(AM43:AM73) -> #DIV/0!
A42: Date | B42: Good | C42: Rework | D42: IN Running REJ. | E42: T.R | F42: Total Qty. | G42: Rework PPM | H42: Rej PPM | I42: TR PPM | K42: Date | L42: Good | M42: Rework | N42: IN Running REJ. | O42: T.R | P42: Total Qty. | Q42: Rework PPM | R42: Rej PPM | S42: TR PPM | U42: Date | V42: Good | W42: Rework | X42: IN Running REJ. | Y42: T.R | Z42: Total Qty. | AA42: Rework PPM | AB42: Rej PPM | AC42: TR PPM
A43: (blank) | B43: =SUMIFS('PD REPORT'!$Q$7:$Q$2070,'PD REPORT'!$D$7:$D$2070,$E$41,'PD REPORT'!$B$7:$B$2070,A43) -> 0 | C43: =SUMIFS('PD REPORT'!$R$7:$R$2070,'PD REPORT'!$D$7:$D$2070,$E$41,'PD REPORT'!$B$7:$B$2070,A43) -> 0 | D43: =SUMIFS('PD REPORT'!$S$7:$S$2070,'PD REPORT'!$D$7:$D$2070,$E$41,'PD REPORT'!$B$7:$B$2070,A43) -> 0 | E43: =SUMIFS('PD REPORT'!$T$7:$T$2070,'PD REPORT'!$D$7:$D$2070,$E$41,'PD REPORT'!$B$7:$B$2070,A43) -> 0 | F43: =SUM(B43:E43) -> 0 | G43: =IFERROR((C43/F43)*1000000,"") | H43: =IFERROR((D43/F43)*1000000,"") | I43: =IFERROR((E43/F43)*1000000,"") | K43: (blank) | L43: =SUMIFS('PD REPORT'!$Q$7:$Q$2070,'PD REPORT'!$D$7:$D$2070,$O$41,'PD REPORT'!$B$7:$B$2070,K43) -> 0 | M43: =SUMIFS('PD REPORT'!$R$7:$R$2070,'PD REPORT'!$D$7:$D$2070,$O$41,'PD REPORT'!$B$7:$B$2070,K43) -> 0 | N43: =SUMIFS('PD REPORT'!$S$7:$S$2070,'PD REPORT'!$D$7:$D$2070,$O$41,'PD REPORT'!$B$7:$B$2070,K43) -> 0 | O43: =SUMIFS('PD REPORT'!$T$7:$T$2070,'PD REPORT'!$D$7:$D$2070,$O$41,'PD REPORT'!$B$7:$B$2070,K43) -> 0 | P43: =SUM(L43:O43) -> 0 | Q43: =IFERROR((M43/P43)*1000000,"") | R43: =IFERROR((N43/P43)*1000000,"") | S43: =IFERROR((O43/P43)*1000000,"") | U43: (blank) | AE43: 46023 | AF43: =SUMIFS('PD REPORT'!$Q$7:$Q$2070,'PD REPORT'!$D$7:$D$2070,$AI$41,'PD REPORT'!$B$7:$B$2070,AE43) -> 0 | AG43: =SUMIFS('PD REPORT'!$R$7:$R$2070,'PD REPORT'!$D$7:$D$2070,$AI$41,'PD REPORT'!$B$7:$B$2070,AE43) -> 0 | AH43: =SUMIFS('PD REPORT'!$S$7:$S$2070,'PD REPORT'!$D$7:$D$2070,$AI$41,'PD REPORT'!$B$7:$B$2070,AE43) -> 0 | AI43: =SUMIFS('PD REPORT'!$T$7:$T$2070,'PD REPORT'!$D$7:$D$2070,$AI$41,'PD REPORT'!$B$7:$B$2070,AE43) -> 0 | AJ43: =SUM(AF43:AI43) -> 0 | AK43: =IFERROR((AG43/AJ43)*1000000,"") | AL43: =IFERROR((AH43/AJ43)*1000000,"") | AM43: =IFERROR((AI43/AJ43)*1000000,"")
A44: 46054 | B44: =SUMIFS('PD REPORT'!$Q$7:$Q$2070,'PD REPORT'!$D$7:$D$2070,$E$41,'PD REPORT'!$B$7:$B$2070,A44) -> 6199 | C44: =SUMIFS('PD REPORT'!$R$7:$R$2070,'PD REPORT'!$D$7:$D$2070,$E$41,'PD REPORT'!$B$7:$B$2070,A44) -> 484 | D44: =SUMIFS('PD REPORT'!$S$7:$S$2070,'PD REPORT'!$D$7:$D$2070,$E$41,'PD REPORT'!$B$7:$B$2070,A44) -> 231 | E44: =SUMIFS('PD REPORT'!$T$7:$T$2070,'PD REPORT'!$D$7:$D$2070,$E$41,'PD REPORT'!$B$7:$B$2070,A44) -> 28 | F44: =SUM(B44:E44) -> 6942 | G44: =IFERROR((C44/F44)*1000000,"") -> 69720.542 | H44: =IFERROR((D44/F44)*1000000,"") -> 33275.713 | I44: =IFERROR((E44/F44)*1000000,"") -> 4033.4198 | K44: 46054 | L44: =SUMIFS('PD REPORT'!$Q$7:$Q$2070,'PD REPORT'!$D$7:$D$2070,$O$41,'PD REPORT'!$B$7:$B$2070,K44) -> 2134 | M44: =SUMIFS('PD REPORT'!$R$7:$R$2070,'PD REPORT'!$D$7:$D$2070,$O$41,'PD REPORT'!$B$7:$B$2070,K44) -> 39 | N44: =SUMIFS('PD REPORT'!$S$7:$S$2070,'PD REPORT'!$D$7:$D$2070,$O$41,'PD REPORT'!$B$7:$B$2070,K44) -> 12 | O44: =SUMIFS('PD REPORT'!$T$7:$T$2070,'PD REPORT'!$D$7:$D$2070,$O$41,'PD REPORT'!$B$7:$B$2070,K44) -> 0 | P44: =SUM(L44:O44) -> 2185 | Q44: =IFERROR((M44/P44)*1000000,"") -> 17848.97 | R44: =IFERROR((N44/P44)*1000000,"") -> 5491.9908 | S44: =IFERROR((O44/P44)*1000000,"") -> 0 | U44: 46054 | V44: =SUMIFS('PD REPORT'!$Q$7:$Q$2070,'PD REPORT'!$D$7:$D$2070,$Y$41,'PD REPORT'!$B$7:$B$2070,U44) -> 13852 | W44: =SUMIFS('PD REPORT'!$R$7:$R$2070,'PD REPORT'!$D$7:$D$2070,$Y$41,'PD REPORT'!$B$7:$B$2070,U44) -> 0 | X44: =SUMIFS('PD REPORT'!$S$7:$S$2070,'PD REPORT'!$D$7:$D$2070,$Y$41,'PD REPORT'!$B$7:$B$2070,U44) -> 5 | Y44: =SUMIFS('PD REPORT'!$T$7:$T$2070,'PD REPORT'!$D$7:$D$2070,$Y$41,'PD REPORT'!$B$7:$B$2070,U44) -> 0 | Z44: =SUM(V44:Y44) -> 13857 | AA44: =IFERROR((W44/Z44)*1000000,"") -> 0 | AB44: =IFERROR((X44/Z44)*1000000,"") -> 360.82846 | AC44: =IFERROR((Y44/Z44)*1000000,"") -> 0 | AE44: 46024 | AF44: =SUMIFS('PD REPORT'!$Q$7:$Q$2070,'PD REPORT'!$D$7:$D$2070,$AI$41,'PD REPORT'!$B$7:$B$2070,AE44) -> 0 | AG44: =SUMIFS('PD REPORT'!$R$7:$R$2070,'PD REPORT'!$D$7:$D$2070,$AI$41,'PD REPORT'!$B$7:$B$2070,AE44) -> 0 | AH44: =SUMIFS('PD REPORT'!$S$7:$S$2070,'PD REPORT'!$D$7:$D$2070,$AI$41,'PD REPORT'!$B$7:$B$2070,AE44) -> 0 | AI44: =SUMIFS('PD REPORT'!$T$7:$T$2070,'PD REPORT'!$D$7:$D$2070,$AI$41,'PD REPORT'!$B$7:$B$2070,AE44) -> 0 | AJ44: =SUM(AF44:AI44) -> 0 | AK44: =IFERROR((AG44/AJ44)*1000000,"") | AL44: =IFERROR((AH44/AJ44)*1000000,"") | AM44: =IFERROR((AI44/AJ44)*1000000,"")
A45: 46055 | B45: =SUMIFS('PD REPORT'!$Q$7:$Q$2070,'PD REPORT'!$D$7:$D$2070,$E$41,'PD REPORT'!$B$7:$B$2070,A45) -> 8052 | C45: =SUMIFS('PD REPORT'!$R$7:$R$2070,'PD REPORT'!$D$7:$D$2070,$E$41,'PD REPORT'!$B$7:$B$2070,A45) -> 364 | D45: =SUMIFS('PD REPORT'!$S$7:$S$2070,'PD REPORT'!$D$7:$D$2070,$E$41,'PD REPORT'!$B$7:$B$2070,A45) -> 255 | E45: =SUMIFS('PD REPORT'!$T$7:$T$2070,'PD REPORT'!$D$7:$D$2070,$E$41,'PD REPORT'!$B$7:$B$2070,A45) -> 32 | F45: =SUM(B45:E45) -> 8703 | G45: =IFERROR((C45/F45)*1000000,"") -> 41824.658 | H45: =IFERROR((D45/F45)*1000000,"") -> 29300.241 | I45: =IFERROR((E45/F45)*1000000,"") -> 3676.893 | K45: 46055 | L45: =SUMIFS('PD REPORT'!$Q$7:$Q$2070,'PD REPORT'!$D$7:$D$2070,$O$41,'PD REPORT'!$B$7:$B$2070,K45) -> 1612 | M45: =SUMIFS('PD REPORT'!$R$7:$R$2070,'PD REPORT'!$D$7:$D$2070,$O$41,'PD REPORT'!$B$7:$B$2070,K45) -> 21 | N45: =SUMIFS('PD REPORT'!$S$7:$S$2070,'PD REPORT'!$D$7:$D$2070,$O$41,'PD REPORT'!$B$7:$B$2070,K45) -> 1 | O45: =SUMIFS('PD REPORT'!$T$7:$T$2070,'PD REPORT'!$D$7:$D$2070,$O$41,'PD REPORT'!$B$7:$B$2070,K45) -> 0 | P45: =SUM(L45:O45) -> 1634 | Q45: =IFERROR((M45/P45)*1000000,"") -> 12851.897 | R45: =IFERROR((N45/P45)*1000000,"") -> 611.9951 | S45: =IFERROR((O45/P45)*1000000,"") -> 0 | U45: 46055 | V45: =SUMIFS('PD REPORT'!$Q$7:$Q$2070,'PD REPORT'!$D$7:$D$2070,$Y$41,'PD REPORT'!$B$7:$B$2070,U45) -> 13797 | W45: =SUMIFS('PD REPORT'!$R$7:$R$2070,'PD REPORT'!$D$7:$D$2070,$Y$41,'PD REPORT'!$B$7:$B$2070,U45) -> 0 | X45: =SUMIFS('PD REPORT'!$S$7:$S$2070,'PD REPORT'!$D$7:$D$2070,$Y$41,'PD REPORT'!$B$7:$B$2070,U45) -> 0 | Y45: =SUMIFS('PD REPORT'!$T$7:$T$2070,'PD REPORT'!$D$7:$D$2070,$Y$41,'PD REPORT'!$B$7:$B$2070,U45) -> 0 | Z45: =SUM(V45:Y45) -> 13797 | AA45: =IFERROR((W45/Z45)*1000000,"") -> 0 | AB45: =IFERROR((X45/Z45)*1000000,"") -> 0 | AC45: =IFERROR((Y45/Z45)*1000000,"") -> 0 | AE45: 46025 | AF45: =SUMIFS('PD REPORT'!$Q$7:$Q$2070,'PD REPORT'!$D$7:$D$2070,$AI$41,'PD REPORT'!$B$7:$B$2070,AE45) -> 0 | AG45: =SUMIFS('PD REPORT'!$R$7:$R$2070,'PD REPORT'!$D$7:$D$2070,$AI$41,'PD REPORT'!$B$7:$B$2070,AE45) -> 0 | AH45: =SUMIFS('PD REPORT'!$S$7:$S$2070,'PD REPORT'!$D$7:$D$2070,$AI$41,'PD REPORT'!$B$7:$B$2070,AE45) -> 0 | AI45: =SUMIFS('PD REPORT'!$T$7:$T$2070,'PD REPORT'!$D$7:$D$2070,$AI$41,'PD REPORT'!$B$7:$B$2070,AE45) -> 0 | AJ45: =SUM(AF45:AI45) -> 0 | AK45: =IFERROR((AG45/AJ45)*1000000,"") | AL45: =IFERROR((AH45/AJ45)*1000000,"") | AM45: =IFERROR((AI45/AJ45)*1000000,"")
A46: 46056 | B46: =SUMIFS('PD REPORT'!$Q$7:$Q$2070,'PD REPORT'!$D$7:$D$2070,$E$41,'PD REPORT'!$B$7:$B$2070,A46) -> 9384 | C46: =SUMIFS('PD REPORT'!$R$7:$R$2070,'PD REPORT'!$D$7:$D$2070,$E$41,'PD REPORT'!$B$7:$B$2070,A46) -> 421 | D46: =SUMIFS('PD REPORT'!$S$7:$S$2070,'PD REPORT'!$D$7:$D$2070,$E$41,'PD REPORT'!$B$7:$B$2070,A46) -> 196 | E46: =SUMIFS('PD REPORT'!$T$7:$T$2070,'PD REPORT'!$D$7:$D$2070,$E$41,'PD REPORT'!$B$7:$B$2070,A46) -> 19 | F46: =SUM(B46:E46) -> 10020 | G46: =IFERROR((C46/F46)*1000000,"") -> 42015.968 | H46: =IFERROR((D46/F46)*1000000,"") -> 19560.878 | I46: =IFERROR((E46/F46)*1000000,"") -> 1896.2076 | K46: 46056 | L46: =SUMIFS('PD REPORT'!$Q$7:$Q$2070,'PD REPORT'!$D$7:$D$2070,$O$41,'PD REPORT'!$B$7:$B$2070,K46) -> 1164 | M46: =SUMIFS('PD REPORT'!$R$7:$R$2070,'PD REPORT'!$D$7:$D$2070,$O$41,'PD REPORT'!$B$7:$B$2070,K46) -> 23 | N46: =SUMIFS('PD REPORT'!$S$7:$S$2070,'PD REPORT'!$D$7:$D$2070,$O$41,'PD REPORT'!$B$7:$B$2070,K46) -> 4 | O46: =SUMIFS('PD REPORT'!$T$7:$T$2070,'PD REPORT'!$D$7:$D$2070,$O$41,'PD REPORT'!$B$7:$B$2070,K46) -> 1 | P46: =SUM(L46:O46) -> 1192 | Q46: =IFERROR((M46/P46)*1000000,"") -> 19295.302 | R46: =IFERROR((N46/P46)*1000000,"") -> 3355.7047 | S46: =IFERROR((O46/P46)*1000000,"") -> 838.92617 | U46: 46056 | V46: =SUMIFS('PD REPORT'!$Q$7:$Q$2070,'PD REPORT'!$D$7:$D$2070,$Y$41,'PD REPORT'!$B$7:$B$2070,U46) -> 24623 | W46: =SUMIFS('PD REPORT'!$R$7:$R$2070,'PD REPORT'!$D$7:$D$2070,$Y$41,'PD REPORT'!$B$7:$B$2070,U46) -> 0 | X46: =SUMIFS('PD REPORT'!$S$7:$S$2070,'PD REPORT'!$D$7:$D$2070,$Y$41,'PD REPORT'!$B$7:$B$2070,U46) -> 2 | Y46: =SUMIFS('PD REPORT'!$T$7:$T$2070,'PD REPORT'!$D$7:$D$2070,$Y$41,'PD REPORT'!$B$7:$B$2070,U46) -> 0 | Z46: =SUM(V46:Y46) -> 24625 | AA46: =IFERROR((W46/Z46)*1000000,"") -> 0 | AB46: =IFERROR((X46/Z46)*1000000,"") -> 81.218274 | AC46: =IFERROR((Y46/Z46)*1000000,"") -> 0 | AE46: 46026 | AF46: =SUMIFS('PD REPORT'!$Q$7:$Q$2070,'PD REPORT'!$D$7:$D$2070,$AI$41,'PD REPORT'!$B$7:$B$2070,AE46) -> 0 | AG46: =SUMIFS('PD REPORT'!$R$7:$R$2070,'PD REPORT'!$D$7:$D$2070,$AI$41,'PD REPORT'!$B$7:$B$2070,AE46) -> 0 | AH46: =SUMIFS('PD REPORT'!$S$7:$S$2070,'PD REPORT'!$D$7:$D$2070,$AI$41,'PD REPORT'!$B$7:$B$2070,AE46) -> 0 | AI46: =SUMIFS('PD REPORT'!$T$7:$T$2070,'PD REPORT'!$D$7:$D$2070,$AI$41,'PD REPORT'!$B$7:$B$2070,AE46) -> 0 | AJ46: =SUM(AF46:AI46) -> 0 | AK46: =IFERROR((AG46/AJ46)*1000000,"") | AL46: =IFERROR((AH46/AJ46)*1000000,"") | AM46: =IFERROR((AI46/AJ46)*1000000,"")
A47: 46057 | B47: =SUMIFS('PD REPORT'!$Q$7:$Q$2070,'PD REPORT'!$D$7:$D$2070,$E$41,'PD REPORT'!$B$7:$B$2070,A47) -> 8186 | C47: =SUMIFS('PD REPORT'!$R$7:$R$2070,'PD REPORT'!$D$7:$D$2070,$E$41,'PD REPORT'!$B$7:$B$2070,A47) -> 380 | D47: =SUMIFS('PD REPORT'!$S$7:$S$2070,'PD REPORT'!$D$7:$D$2070,$E$41,'PD REPORT'!$B$7:$B$2070,A47) -> 177 | E47: =SUMIFS('PD REPORT'!$T$7:$T$2070,'PD REPORT'!$D$7:$D$2070,$E$41,'PD REPORT'!$B$7:$B$2070,A47) -> 7 | F47: =SUM(B47:E47) -> 8750 | G47: =IFERROR((C47/F47)*1000000,"") -> 43428.571 | H47: =IFERROR((D47/F47)*1000000,"") -> 20228.571 | I47: =IFERROR((E47/F47)*1000000,"") -> 800 | K47: 46057 | L47: =SUMIFS('PD REPORT'!$Q$7:$Q$2070,'PD REPORT'!$D$7:$D$2070,$O$41,'PD REPORT'!$B$7:$B$2070,K47) -> 2180 | M47: =SUMIFS('PD REPORT'!$R$7:$R$2070,'PD REPORT'!$D$7:$D$2070,$O$41,'PD REPORT'!$B$7:$B$2070,K47) -> 15 | N47: =SUMIFS('PD REPORT'!$S$7:$S$2070,'PD REPORT'!$D$7:$D$2070,$O$41,'PD REPORT'!$B$7:$B$2070,K47) -> 6 | O47: =SUMIFS('PD REPORT'!$T$7:$T$2070,'PD REPORT'!$D$7:$D$2070,$O$41,'PD REPORT'!$B$7:$B$2070,K47) -> 0 | P47: =SUM(L47:O47) -> 2201 | Q47: =IFERROR((M47/P47)*1000000,"") -> 6815.0841 | R47: =IFERROR((N47/P47)*1000000,"") -> 2726.0336 | S47: =IFERROR((O47/P47)*1000000,"") -> 0 | U47: 46057 | V47: =SUMIFS('PD REPORT'!$Q$7:$Q$2070,'PD REPORT'!$D$7:$D$2070,$Y$41,'PD REPORT'!$B$7:$B$2070,U47) -> 12000 | W47: =SUMIFS('PD REPORT'!$R$7:$R$2070,'PD REPORT'!$D$7:$D$2070,$Y$41,'PD REPORT'!$B$7:$B$2070,U47) -> 0 | X47: =SUMIFS('PD REPORT'!$S$7:$S$2070,'PD REPORT'!$D$7:$D$2070,$Y$41,'PD REPORT'!$B$7:$B$2070,U47) -> 0 | Y47: =SUMIFS('PD REPORT'!$T$7:$T$2070,'PD REPORT'!$D$7:$D$2070,$Y$41,'PD REPORT'!$B$7:$B$2070,U47) -> 0 | Z47: =SUM(V47:Y47) -> 12000 | AA47: =IFERROR((W47/Z47)*1000000,"") -> 0 | AB47: =IFERROR((X47/Z47)*1000000,"") -> 0 | AC47: =IFERROR((Y47/Z47)*1000000,"") -> 0 | AE47: 46027 | AF47: =SUMIFS('PD REPORT'!$Q$7:$Q$2070,'PD REPORT'!$D$7:$D$2070,$AI$41,'PD REPORT'!$B$7:$B$2070,AE47) -> 0 | AG47: =SUMIFS('PD REPORT'!$R$7:$R$2070,'PD REPORT'!$D$7:$D$2070,$AI$41,'PD REPORT'!$B$7:$B$2070,AE47) -> 0 | AH47: =SUMIFS('PD REPORT'!$S$7:$S$2070,'PD REPORT'!$D$7:$D$2070,$AI$41,'PD REPORT'!$B$7:$B$2070,AE47) -> 0 | AI47: =SUMIFS('PD REPORT'!$T$7:$T$2070,'PD REPORT'!$D$7:$D$2070,$AI$41,'PD REPORT'!$B$7:$B$2070,AE47) -> 0 | AJ47: =SUM(AF47:AI47) -> 0 | AK47: =IFERROR((AG47/AJ47)*1000000,"") | AL47: =IFERROR((AH47/AJ47)*1000000,"") | AM47: =IFERROR((AI47/AJ47)*1000000,"")
A48: 46058 | B48: =SUMIFS('PD REPORT'!$Q$7:$Q$2070,'PD REPORT'!$D$7:$D$2070,$E$41,'PD REPORT'!$B$7:$B$2070,A48) -> 8355 | C48: =SUMIFS('PD REPORT'!$R$7:$R$2070,'PD REPORT'!$D$7:$D$2070,$E$41,'PD REPORT'!$B$7:$B$2070,A48) -> 295 | D48: =SUMIFS('PD REPORT'!$S$7:$S$2070,'PD REPORT'!$D$7:$D$2070,$E$41,'PD REPORT'!$B$7:$B$2070,A48) -> 195 | E48: =SUMIFS('PD REPORT'!$T$7:$T$2070,'PD REPORT'!$D$7:$D$2070,$E$41,'PD REPORT'!$B$7:$B$2070,A48) -> 20 | F48: =SUM(B48:E48) -> 8865 | G48: =IFERROR((C48/F48)*1000000,"") -> 33276.932 | H48: =IFERROR((D48/F48)*1000000,"") -> 21996.616 | I48: =IFERROR((E48/F48)*1000000,"") -> 2256.0632 | K48: 46058 | L48: =SUMIFS('PD REPORT'!$Q$7:$Q$2070,'PD REPORT'!$D$7:$D$2070,$O$41,'PD REPORT'!$B$7:$B$2070,K48) -> 4425 | M48: =SUMIFS('PD REPORT'!$R$7:$R$2070,'PD REPORT'!$D$7:$D$2070,$O$41,'PD REPORT'!$B$7:$B$2070,K48) -> 8 | N48: =SUMIFS('PD REPORT'!$S$7:$S$2070,'PD REPORT'!$D$7:$D$2070,$O$41,'PD REPORT'!$B$7:$B$2070,K48) -> 1 | O48: =SUMIFS('PD REPORT'!$T$7:$T$2070,'PD REPORT'!$D$7:$D$2070,$O$41,'PD REPORT'!$B$7:$B$2070,K48) -> 0 | P48: =SUM(L48:O48) -> 4434 | Q48: =IFERROR((M48/P48)*1000000,"") -> 1804.24 | R48: =IFERROR((N48/P48)*1000000,"") -> 225.53 | S48: =IFERROR((O48/P48)*1000000,"") -> 0 | U48: 46058 | V48: =SUMIFS('PD REPORT'!$Q$7:$Q$2070,'PD REPORT'!$D$7:$D$2070,$Y$41,'PD REPORT'!$B$7:$B$2070,U48) -> 19181 | W48: =SUMIFS('PD REPORT'!$R$7:$R$2070,'PD REPORT'!$D$7:$D$2070,$Y$41,'PD REPORT'!$B$7:$B$2070,U48) -> 0 | X48: =SUMIFS('PD REPORT'!$S$7:$S$2070,'PD REPORT'!$D$7:$D$2070,$Y$41,'PD REPORT'!$B$7:$B$2070,U48) -> 4 | Y48: =SUMIFS('PD REPORT'!$T$7:$T$2070,'PD REPORT'!$D$7:$D$2070,$Y$41,'PD REPORT'!$B$7:$B$2070,U48) -> 0 | Z48: =SUM(V48:Y48) -> 19185 | AA48: =IFERROR((W48/Z48)*1000000,"") -> 0 | AB48: =IFERROR((X48/Z48)*1000000,"") -> 208.49622 | AC48: =IFERROR((Y48/Z48)*1000000,"") -> 0 | AE48: 46028 | AF48: =SUMIFS('PD REPORT'!$Q$7:$Q$2070,'PD REPORT'!$D$7:$D$2070,$AI$41,'PD REPORT'!$B$7:$B$2070,AE48) -> 0 | AG48: =SUMIFS('PD REPORT'!$R$7:$R$2070,'PD REPORT'!$D$7:$D$2070,$AI$41,'PD REPORT'!$B$7:$B$2070,AE48) -> 0 | AH48: =SUMIFS('PD REPORT'!$S$7:$S$2070,'PD REPORT'!$D$7:$D$2070,$AI$41,'PD REPORT'!$B$7:$B$2070,AE48) -> 0 | AI48: =SUMIFS('PD REPORT'!$T$7:$T$2070,'PD REPORT'!$D$7:$D$2070,$AI$41,'PD REPORT'!$B$7:$B$2070,AE48) -> 0 | AJ48: =SUM(AF48:AI48) -> 0 | AK48: =IFERROR((AG48/AJ48)*1000000,"") | AL48: =IFERROR((AH48/AJ48)*1000000,"") | AM48: =IFERROR((AI48/AJ48)*1000000,"")
A49: 46059 | B49: =SUMIFS('PD REPORT'!$Q$7:$Q$2070,'PD REPORT'!$D$7:$D$2070,$E$41,'PD REPORT'!$B$7:$B$2070,A49) -> 9442 | C49: =SUMIFS('PD REPORT'!$R$7:$R$2070,'PD REPORT'!$D$7:$D$2070,$E$41,'PD REPORT'!$B$7:$B$2070,A49) -> 366 | D49: =SUMIFS('PD REPORT'!$S$7:$S$2070,'PD REPORT'!$D$7:$D$2070,$E$41,'PD REPORT'!$B$7:$B$2070,A49) -> 196 | E49: =SUMIFS('PD REPORT'!$T$7:$T$2070,'PD REPORT'!$D$7:$D$2070,$E$41,'PD REPORT'!$B$7:$B$2070,A49) -> 61 | F49: =SUM(B49:E49) -> 10065 | G49: =IFERROR((C49/F49)*1000000,"") -> 36363.636 | H49: =IFERROR((D49/F49)*1000000,"") -> 19473.423 | I49: =IFERROR((E49/F49)*1000000,"") -> 6060.6061 | K49: 46059 | L49: =SUMIFS('PD REPORT'!$Q$7:$Q$2070,'PD REPORT'!$D$7:$D$2070,$O$41,'PD REPORT'!$B$7:$B$2070,K49) -> 3726 | M49: =SUMIFS('PD REPORT'!$R$7:$R$2070,'PD REPORT'!$D$7:$D$2070,$O$41,'PD REPORT'!$B$7:$B$2070,K49) -> 16 | N49: =SUMIFS('PD REPORT'!$S$7:$S$2070,'PD REPORT'!$D$7:$D$2070,$O$41,'PD REPORT'!$B$7:$B$2070,K49) -> 0 | O49: =SUMIFS('PD REPORT'!$T$7:$T$2070,'PD REPORT'!$D$7:$D$2070,$O$41,'PD REPORT'!$B$7:$B$2070,K49) -> 0 | P49: =SUM(L49:O49) -> 3742 | Q49: =IFERROR((M49/P49)*1000000,"") -> 4275.7883 | R49: =IFERROR((N49/P49)*1000000,"") -> 0 | S49: =IFERROR((O49/P49)*1000000,"") -> 0 | U49: 46059 | V49: =SUMIFS('PD REPORT'!$Q$7:$Q$2070,'PD REPORT'!$D$7:$D$2070,$Y$41,'PD REPORT'!$B$7:$B$2070,U49) -> 18776 | W49: =SUMIFS('PD REPORT'!$R$7:$R$2070,'PD REPORT'!$D$7:$D$2070,$Y$41,'PD REPORT'!$B$7:$B$2070,U49) -> 0 | X49: =SUMIFS('PD REPORT'!$S$7:$S$2070,'PD REPORT'!$D$7:$D$2070,$Y$41,'PD REPORT'!$B$7:$B$2070,U49) -> 2 | Y49: =SUMIFS('PD REPORT'!$T$7:$T$2070,'PD REPORT'!$D$7:$D$2070,$Y$41,'PD REPORT'!$B$7:$B$2070,U49) -> 0 | Z49: =SUM(V49:Y49) -> 18778 | AA49: =IFERROR((W49/Z49)*1000000,"") -> 0 | AB49: =IFERROR((X49/Z49)*1000000,"") -> 106.50762 | AC49: =IFERROR((Y49/Z49)*1000000,"") -> 0 | AE49: 46029 | AF49: =SUMIFS('PD REPORT'!$Q$7:$Q$2070,'PD REPORT'!$D$7:$D$2070,$AI$41,'PD REPORT'!$B$7:$B$2070,AE49) -> 0 | AG49: =SUMIFS('PD REPORT'!$R$7:$R$2070,'PD REPORT'!$D$7:$D$2070,$AI$41,'PD REPORT'!$B$7:$B$2070,AE49) -> 0 | AH49: =SUMIFS('PD REPORT'!$S$7:$S$2070,'PD REPORT'!$D$7:$D$2070,$AI$41,'PD REPORT'!$B$7:$B$2070,AE49) -> 0 | AI49: =SUMIFS('PD REPORT'!$T$7:$T$2070,'PD REPORT'!$D$7:$D$2070,$AI$41,'PD REPORT'!$B$7:$B$2070,AE49) -> 0 | AJ49: =SUM(AF49:AI49) -> 0 | AK49: =IFERROR((AG49/AJ49)*1000000,"") | AL49: =IFERROR((AH49/AJ49)*1000000,"") | AM49: =IFERROR((AI49/AJ49)*1000000,"")
...

Sheet MACHINE
A1: Operator | B1: Machine | C1: Operation
A2: Raymalbhai Bharathiya | B2: IG.01 | C2: SFODG
A3: Bilal | B3: IG.04 | C3: FODG
A4: Deval | B4: IG.11 | C4: RODG
A5: Pawan | B5: IG.12 | C5: FG
A6: Baldev Dabhi | B6: IG.13 | C6: RFG
A7: Kishan K | B7: IG.14 | C7: TG
A8: Hritik singh | B8: IG.15 | C8: RTG
A9: Dharmendra | B9: IG.16 | C9: CODG
A10: Dilip Panday | B10: IG.17 | C10: BG
A11: Kishan Garthiya | B11: IG.18 | C11: RBG
A12: Jaglal Gupta | B12: HO.02 | C12: HONING
... A18: Kaushik Vasveliya | B18: HO.08 OR | C18: Washar
A19: Ketan | B19: HO.09 IR
A20: Pankajbhai Khasiya | B20: HO.09 OR
A21: Kishan | B21: FG.03
A22: Taslimbhai Kondhiya | B22: FG.04
A23: Rahul Loladiya | B23: CG.02
A24: Badriprasad Mali | B24: CG.03
A25: Varshaben Mankoliya | B25: CG.04
A26: Manojbhai | B26: EG.02
A27: Nihar Sheth | B27: EG.04
A28: Ramdeen Nishad | B28: EG.05
A29: Pankaj Oganiya | B29: EG.07
A30: Rinaben Oganiya | B30: HO.10
... A35: Pravin Baraiya | B35: EG.03
A36: Abhijitsinh Rana
A37: Parulben Ranga
A38: Nareshbhai Rathod
A39: Ravikumar Sharma
A40: Rutvik
A41: Sanjay
A42: Shamjibhai Satapara
A43: Ramesh Shakriya
A44: Umang
A45: Kiran Vaghadiya
A46: Kalpeshbhai Vasoya
A47: Vishal Danavadiya
... A108: Kishor Kumar
AY344: 540
...

Sheet KPI Data
A1: Production KPI Data Jan-2026
A2: 21 | B2: PD-01 | C2: Process capability Index | D2: ≥ 1.67 | E2: 1.67 | F2: 1.35
A3: 22 | B3: PD-02 | C3: Production achievement against planned rings | D3: >95 % | E3: 95 | F3: 69
A4: 24 | B4: PD-04 | C4: Rejection of IR / OR Face Grinding operation | D4: < 400 ppm | E4: 400 | F4: ='Backend Data for KPI'!AB41 -> 162.06743
A5: 25 | B5: PD-05 | C5: Soft Machining Rejection IR / OR while Face Grinding operation | D5: <150 ppm | E5: 150 | F5: ='Backend Data for KPI'!AC41 -> 4.9775017
A6: 26 | B6: PD-06 | C6: Turning Rejection of IR / OR while Center less Grinding operation | D6: <1000 ppm | E6: 1000 | F6: ='Backend Data for KPI'!AM41 -> #DIV/0!
A7: 27 | B7: PD-07 | C7: Rejection of IR-OR / IG Grinding operation | D7: <1500 ppm | E7: 1500 | F7: ='Backend Data for KPI'!H41 -> 21360.911
A8: 28 | B8: PD-08 | C8: Rejection of IR -OR EG Grinding operation | D8: <1500 ppm | E8: 1500 | F8: ='Backend Data for KPI'!R41 -> 1939.1249
B9: PD-09 | C9: Rework of IR/OR IG operation | D9: <7500 ppm | E9: 7500 | F9: ='Backend Data for KPI'!G41 -> 36255.989
B10: PD-10 | C10: Rework of IR/OR EG operation | D10: <3000 ppm | E10: 3000 | F10: ='Backend Data for KPI'!Q41 -> 7637.6717
A11: 29 | B11: PD-11 | C11: Turning Rejection of IR/OR while IG/EG Grinding operation | D11: <700 ppm | E11: 700 | F11: ='Backend Data for KPI'!G93 -> 161.80153
A12: 31 | B12: PD-13 | C12: Average output per person Production | D12: >5000 | E12: 5000
A13: 32 | B13: PD-14 | C13: Finished ring inventory | D13: <20% of sales | E13: 20
A14: 33 | B14: PD-15 | C14: Lead time monitoring of route card up to WIP | D14: >90% within 25 days | E14: 90
A15: 34 | B15: PD-16 | C15: OEE Monitoring | D15: > 65% | E15: 65

Sheet Graph
H1: IG Sectionn Graph KPI Data | L1: PD-07 | M1: PD-09
A3: M | B3: 1
A4: 50 | B4: 100
A5: 10 | B5: 3000
A6: 30 | B6: 4000
H23: EG Sectionn Graph KPI Data | L23: PD-10 | M23: PD-08
H44: FG Sectionn Graph KPI Data | L44: PD-04 | M44: PD-05
H66: IG & EG Sectionn Graph KPI Data | L66: PD-11

Sheet Sheet1
J16: \
J17: 123456789
E19: ZXCVBNMASDFGHJKLQWERTYUIOP[]=-0987654321``
E20: C]-;pgrh]E;G
